<?xml version="1.0" encoding="utf-8"?>
<!-- =================================================================================== -->
<!-- |    This document was autogenerated by xacro from hera_full.urdf.xacro           | -->
<!-- |    EDITING THIS FILE BY HAND IS NOT RECOMMENDED                                 | -->
<!-- =================================================================================== -->
<robot name="hera" xmlns:controller="http://playerstage.sourceforge.net/gazebo/xmlschema/#controller" xmlns:interface="http://playerstage.sourceforge.net/gazebo/xmlschema/#interface" xmlns:sensor="http://playerstage.sourceforge.net/gazebo/xmlschema/#sensor">
  <!-- <xacro:arg name="prefix" default="" /> -->
  <!-- ##################################################################### -->
  <!-- ######################### includes ################################## -->
  <!-- ##################################################################### -->
  <!-- colors -->
  <material name="black">
    <color rgba="0.0 0.0 0.0 1.0"/>
  </material>
  <material name="dark_grey">
    <color rgba="0.25 0.25 0.25 1.0"/>
  </material>
  <material name="grey">
    <color rgba="0.5 0.5 0.5 1.0"/>
  </material>
  <material name="light_grey">
    <color rgba="0.75 0.75 0.75 1.0"/>
  </material>
  <material name="white">
    <color rgba="1.0 1.0 1.0 1.0"/>
  </material>
  <!-- Macros -->
  <!-- hera colors -->
  <gazebo reference="base">
    <material>Gazebo/Black</material>
  </gazebo>
  <gazebo reference="base_wheelFR">
    <material>Gazebo/White</material>
  </gazebo>
  <gazebo reference="base_wheelFL">
    <material>Gazebo/White</material>
  </gazebo>
  <gazebo reference="base_wheelBR">
    <material>Gazebo/White</material>
  </gazebo>
  <gazebo reference="base_wheelBL">
    <material>Gazebo/White</material>
  </gazebo>
  <gazebo reference="torso">
    <material>Gazebo/DarkGray</material>
  </gazebo>
  <gazebo reference="torso_sensor_plat">
    <material>Gazebo/DarkGray</material>
  </gazebo>
  <gazebo reference="head">
    <material>Gazebo/Gray</material>
  </gazebo>
  <!-- manip colors -->
  <gazebo reference="base_link">
    <material>Gazebo/Gray</material>
  </gazebo>
  <gazebo reference="link_1">
    <material>Gazebo/Gray</material>
  </gazebo>
  <gazebo reference="link_2">
    <material>Gazebo/Gray</material>
  </gazebo>
  <gazebo reference="link_3">
    <material>Gazebo/Gray</material>
  </gazebo>
  <gazebo reference="link_4">
    <material>Gazebo/Gray</material>
  </gazebo>
  <gazebo reference="link_5">
    <material>Gazebo/Gray</material>
  </gazebo>
  <gazebo reference="link_6">
    <material>Gazebo/Gray</material>
  </gazebo>
  <gazebo reference="palm">
    <material>Gazebo/White</material>
  </gazebo>
  <gazebo reference="tool0">
    <material>Gazebo/White</material>
  </gazebo>
  <gazebo reference="finger_1_link_0">
    <material>Gazebo/White</material>
  </gazebo>
  <gazebo reference="finger_1_link_1">
    <material>Gazebo/White</material>
  </gazebo>
  <gazebo reference="finger_1_link_2">
    <material>Gazebo/White</material>
  </gazebo>
  <gazebo reference="finger_1_link_3">
    <material>Gazebo/White</material>
  </gazebo>
  <gazebo reference="finger_2_link_0">
    <material>Gazebo/White</material>
  </gazebo>
  <gazebo reference="finger_2_link_1">
    <material>Gazebo/White</material>
  </gazebo>
  <gazebo reference="finger_2_link_2">
    <material>Gazebo/White</material>
  </gazebo>
  <gazebo reference="finger_2_link_3">
    <material>Gazebo/White</material>
  </gazebo>
  <gazebo reference="finger_middle_link_0">
    <material>Gazebo/White</material>
  </gazebo>
  <gazebo reference="finger_middle_link_1">
    <material>Gazebo/White</material>
  </gazebo>
  <gazebo reference="finger_middle_link_2">
    <material>Gazebo/White</material>
  </gazebo>
  <gazebo reference="finger_middle_link_3">
    <material>Gazebo/White</material>
  </gazebo>
  <gazebo>
    <plugin filename="libgazebo_ros_control.so" name="gazebo_ros_control"/>
  </gazebo>
  <!-- ####################################################################### -->
  <!-- ######################## robot parts ################################## -->
  <!-- ####################################################################### -->
  <!-- footprint -->
  <link name="base_footprint"/>
  <joint name="joint_base_footprint_to_base" type="fixed">
    <origin xyz="0 0 0.1"/>
    <parent link="base_footprint"/>
    <child link="base"/>
  </joint>
  <!-- base -->
  <link name="base">
    <inertial>
      <mass value="100.0"/>
      <inertia ixx="0.790833333333" ixy="0.0" ixz="0.0" iyy="2.12416666667" iyz="0.0" izz="2.83333333333"/>
    </inertial>
    <collision name="collision">
      <origin rpy="0 0 0" xyz="0 0 0"/>
      <geometry>
        <box size="0.5 0.3 0.07"/>
      </geometry>
    </collision>
    <visual>
      <material name="black"/>
      <geometry>
        <mesh filename="package://hera_description/meshes/base.stl"/>
      </geometry>
    </visual>
  </link>
  <link name="base_wheelFR">
    <inertial>
      <mass value="2.5"/>
      <inertia ixx="0.00727083333333" ixy="0.0" ixz="0.0" iyy="0.00727083333333" iyz="0.0" izz="0.0125"/>
    </inertial>
    <collision name="collision">
      <origin rpy="1.57079632679 0 0" xyz="0 0 0"/>
      <geometry>
        <cylinder length="0.07" radius="0.1"/>
      </geometry>
    </collision>
    <visual>
      <origin rpy=" 0 0 -1.57079632679" xyz="0 -0.045 0"/>
      <material name="white"/>
      <geometry>
        <mesh filename="package://hera_description/meshes/wheelF.stl"/>
      </geometry>
    </visual>
    <inertial>
      <mass value="0.001"/>
      <inertia ixx="1e-08" ixy="0.0" ixz="0.0" iyy="1e-08" iyz="0.0" izz="1e-08"/>
    </inertial>
    <collision name="collision">
      <origin rpy="0 0 0" xyz="0 0 -0.1"/>
      <geometry>
        <sphere radius="0.005"/>
      </geometry>
    </collision>
    <!-- wheel suport -->
  </link>
  <!-- should be continuous. Change if you do not use wheel support -->
  <joint name="joint_base_to_base_wheelFR" type="fixed">
    <origin rpy="0 0 0" xyz="0.2 -0.205 0.0"/>
    <parent link="base"/>
    <child link="base_wheelFR"/>
    <!-- enable when joint type is continuous -->
    <!-- <axis xyz="0 1 0"/> -->
    <!-- <limit effort="${wheel_effort}" velocity="${wheel_velocity}"/> -->
  </joint>
  <link name="base_wheelFL">
    <inertial>
      <mass value="2.5"/>
      <inertia ixx="0.00727083333333" ixy="0.0" ixz="0.0" iyy="0.00727083333333" iyz="0.0" izz="0.0125"/>
    </inertial>
    <collision name="collision">
      <origin rpy="1.57079632679 0 0" xyz="0 0 0"/>
      <geometry>
        <cylinder length="0.07" radius="0.1"/>
      </geometry>
    </collision>
    <visual>
      <origin rpy=" 0 0 1.57079632679" xyz="0 0.045 0"/>
      <material name="white"/>
      <geometry>
        <mesh filename="package://hera_description/meshes/wheelF.stl"/>
      </geometry>
    </visual>
    <inertial>
      <mass value="0.001"/>
      <inertia ixx="1e-08" ixy="0.0" ixz="0.0" iyy="1e-08" iyz="0.0" izz="1e-08"/>
    </inertial>
    <collision name="collision">
      <origin rpy="0 0 0" xyz="0 0 -0.1"/>
      <geometry>
        <sphere radius="0.005"/>
      </geometry>
    </collision>
    <!-- wheel suport -->
  </link>
  <!-- should be continuous. Change if you do not use wheel support -->
  <joint name="joint_base_to_base_wheelFL" type="fixed">
    <origin rpy="0 0 0" xyz="0.2 0.205 0.0"/>
    <parent link="base"/>
    <child link="base_wheelFL"/>
    <!-- enable when joint type is continuous -->
    <!-- <axis xyz="0 1 0"/> -->
    <!-- <limit effort="${wheel_effort}" velocity="${wheel_velocity}"/> -->
  </joint>
  <link name="base_wheelBR">
    <inertial>
      <mass value="2.5"/>
      <inertia ixx="0.00727083333333" ixy="0.0" ixz="0.0" iyy="0.00727083333333" iyz="0.0" izz="0.0125"/>
    </inertial>
    <collision name="collision">
      <origin rpy="1.57079632679 0 0" xyz="0 0 0"/>
      <geometry>
        <cylinder length="0.07" radius="0.1"/>
      </geometry>
    </collision>
    <visual>
      <origin rpy="0 0 -1.57079632679" xyz="0 -0.045 0"/>
      <material name="white"/>
      <geometry>
        <mesh filename="package://hera_description/meshes/wheelB.stl"/>
      </geometry>
    </visual>
    <inertial>
      <mass value="0.001"/>
      <inertia ixx="1e-08" ixy="0.0" ixz="0.0" iyy="1e-08" iyz="0.0" izz="1e-08"/>
    </inertial>
    <collision name="collision">
      <origin rpy="0 0 0" xyz="0 0 -0.1"/>
      <geometry>
        <sphere radius="0.005"/>
      </geometry>
    </collision>
    <!-- wheel suport -->
  </link>
  <!-- should be continuous. Change if you do not use wheel support -->
  <joint name="joint_base_to_base_wheelBR" type="fixed">
    <origin rpy="0 0 0" xyz="-0.2 -0.205 0.0"/>
    <parent link="base"/>
    <child link="base_wheelBR"/>
    <!-- enable when joint type is continuous -->
    <!-- <axis xyz="0 1 0"/> -->
    <!-- <limit effort="${wheel_effort}" velocity="${wheel_velocity}"/> -->
  </joint>
  <link name="base_wheelBL">
    <inertial>
      <mass value="2.5"/>
      <inertia ixx="0.00727083333333" ixy="0.0" ixz="0.0" iyy="0.00727083333333" iyz="0.0" izz="0.0125"/>
    </inertial>
    <collision name="collision">
      <origin rpy="1.57079632679 0 0" xyz="0 0 0"/>
      <geometry>
        <cylinder length="0.07" radius="0.1"/>
      </geometry>
    </collision>
    <visual>
      <origin rpy="0 0 1.57079632679" xyz="0 0.045 0"/>
      <material name="white"/>
      <geometry>
        <mesh filename="package://hera_description/meshes/wheelB.stl"/>
      </geometry>
    </visual>
    <inertial>
      <mass value="0.001"/>
      <inertia ixx="1e-08" ixy="0.0" ixz="0.0" iyy="1e-08" iyz="0.0" izz="1e-08"/>
    </inertial>
    <collision name="collision">
      <origin rpy="0 0 0" xyz="0 0 -0.1"/>
      <geometry>
        <sphere radius="0.005"/>
      </geometry>
    </collision>
    <!-- wheel suport -->
  </link>
  <!-- should be continuous. Change if you do not use wheel support -->
  <joint name="joint_base_to_base_wheelBL" type="fixed">
    <origin rpy="0 0 0" xyz="-0.2 0.205 0.0"/>
    <parent link="base"/>
    <child link="base_wheelBL"/>
    <!-- enable when joint type is continuous -->
    <!-- <axis xyz="0 1 0"/> -->
    <!-- <limit effort="${wheel_effort}" velocity="${wheel_velocity}"/> -->
  </joint>
  <!-- torso -->
  <link name="torso">
    <inertial>
      <mass value="1.0"/>
      <inertia ixx="0.0327083333333" ixy="0.0" ixz="0.0" iyy="0.0327083333333" iyz="0.0" izz="0.015"/>
    </inertial>
    <collision name="collision">
      <origin rpy="0 0 0" xyz="-0.1 0 -0.225"/>
      <geometry>
        <box size="0.3 0.3 0.55"/>
      </geometry>
    </collision>
    <inertial>
      <mass value="0.5"/>
      <inertia ixx="0.0075" ixy="0.0" ixz="0.0" iyy="0.00541666666667" iyz="0.0" izz="0.00541666666667"/>
    </inertial>
    <collision name="collision">
      <origin rpy="0 0 0" xyz="0.15 0 -0.35"/>
      <geometry>
        <box size="0.2 0.3 0.3"/>
      </geometry>
    </collision>
    <inertial>
      <mass value="0.1"/>
      <inertia ixx="0.000770833333333" ixy="0.0" ixz="0.0" iyy="0.00104166666667" iyz="0.0" izz="0.00177083333333"/>
    </inertial>
    <collision name="collision">
      <origin rpy="0 0 0" xyz="-0.06 0 0.475"/>
      <geometry>
        <box size="0.35 0.3 0.05"/>
      </geometry>
    </collision>
    <inertial>
      <mass value="0.2"/>
      <inertia ixx="0.0167266666667" ixy="0.0" ixz="0.0" iyy="0.0169483333333" iyz="0.0" izz="0.000341666666667"/>
    </inertial>
    <collision name="collision">
      <origin rpy="0 0 0" xyz="-0.06 -0.18 0"/>
      <geometry>
        <box size="0.13 0.06 1.0"/>
      </geometry>
    </collision>
    <inertial>
      <mass value="0.2"/>
      <inertia ixx="0.0167266666667" ixy="0.0" ixz="0.0" iyy="0.0169483333333" iyz="0.0" izz="0.000341666666667"/>
    </inertial>
    <collision name="collision">
      <origin rpy="0 0 0" xyz="-0.06 0.18 0"/>
      <geometry>
        <box size="0.13 0.06 1.0"/>
      </geometry>
    </collision>
    <visual>
      <origin rpy="0 0 0" xyz="0 0 -0.5"/>
      <material name="dark_grey"/>
      <geometry>
        <mesh filename="package://hera_description/meshes/torso.stl"/>
      </geometry>
    </visual>
    <collision>
      <origin rpy="0 0 0" xyz="0 0 -0.5"/>
      <material name="dark_grey"/>
      <geometry>
        <mesh filename="package://hera_description/meshes/torso.stl"/>
      </geometry>
    </collision>
  </link>
  <!-- sensor plat -->
  <link name="torso_sensor_plat">
    <inertial>
      <mass value="1.0"/>
      <inertia ixx="0.00120833333333" ixy="0.0" ixz="0.0" iyy="0.000841666666667" iyz="0.0" izz="0.00203333333333"/>
    </inertial>
    <collision name="collision">
      <origin rpy="0 0 0" xyz="0 0 0.05"/>
      <geometry>
        <box size="0.1 0.12 0.01"/>
      </geometry>
    </collision>
    <visual>
      <origin rpy="0 0 0" xyz="0.2 0 -0.2"/>
      <material name="dark_grey"/>
      <geometry>
        <mesh filename="package://hera_description/meshes/torso_sensor_plat.stl"/>
      </geometry>
    </visual>
  </link>
  <joint name="joint_base_to_torso" type="fixed">
    <origin rpy="0 0 0" xyz="0 0 0.535"/>
    <parent link="base"/>
    <child link="torso"/>
  </joint>
  <!-- should be revolute -->
  <joint name="joint_torso_to_torso_sensor_plat" type="revolute">
    <origin rpy="0 0 0" xyz="0.09 0 0.46"/>
    <!-- rpy="0 0 0" -->
    <parent link="torso"/>
    <child link="torso_sensor_plat"/>
    <axis xyz="0 1 0"/>
     --&gt;
      
    <limit effort="30" lower="0.0" upper="1.57" velocity="0.5"/>
  </joint>
  <!-- Transmission to Gazebo Plugin -->
  <transmission name="trans_kinect">
    <type>transmission_interface/SimpleTransmission</type>
    <joint name="joint_torso_to_torso_sensor_plat">
      <hardwareInterface>hardware_interface/EffortJointInterface</hardwareInterface>
    </joint>
    <actuator name="kinect_motor">
      <hardwareInterface>hardware_interface/EffortJointInterface</hardwareInterface>
      <mechanicalReduction>1</mechanicalReduction>
    </actuator>
  </transmission>
  <!-- head -->
  <link name="head">
    <inertial>
      <mass value="0.01"/>
      <inertia ixx="1.35625e-05" ixy="0.0" ixz="0.0" iyy="1.35625e-05" iyz="0.0" izz="2.1125e-05"/>
    </inertial>
    <collision name="collision">
      <origin rpy="0 0 0" xyz="0 0 -0.165"/>
      <geometry>
        <cylinder length="0.06" radius="0.065"/>
      </geometry>
    </collision>
    <inertial>
      <mass value="0.02"/>
      <inertia ixx="0.000188166666667" ixy="0.0" ixz="0.0" iyy="0.000138166666667" iyz="0.0" izz="8.33333333333e-05"/>
    </inertial>
    <collision name="collision">
      <origin rpy="0 0 0" xyz="0 0 0"/>
      <geometry>
        <box size="0.1 0.2 0.27"/>
      </geometry>
    </collision>
    <inertial>
      <mass value="0.01"/>
      <inertia ixx="2.50833333333e-05" ixy="0.0" ixz="0.0" iyy="2.50833333333e-05" iyz="0.0" izz="2e-06"/>
    </inertial>
    <collision name="collision">
      <origin rpy="0 1.45 0" xyz="0.04 -0.13 0.05"/>
      <geometry>
        <cylinder length="0.17" radius="0.02"/>
      </geometry>
    </collision>
    <inertial>
      <mass value="0.01"/>
      <inertia ixx="2.50833333333e-05" ixy="0.0" ixz="0.0" iyy="2.50833333333e-05" iyz="0.0" izz="2e-06"/>
    </inertial>
    <collision name="collision">
      <origin rpy="0 1.45 0" xyz="0.04 0.13 0.05"/>
      <geometry>
        <cylinder length="0.17" radius="0.02"/>
      </geometry>
    </collision>
    <visual>
      <origin rpy="0 0 0" xyz="0 0 -0.195"/>
      <material name="grey"/>
      <geometry>
        <mesh filename="package://hera_description/meshes/head.stl"/>
      </geometry>
    </visual>
  </link>
  <joint name="joint_torso_to_head" type="revolute">
    <origin rpy="0 0 0" xyz="-0.06 0 0.695"/>
    <child link="head"/>
    <parent link="torso"/>
    <axis xyz="0 0 1"/>
    <limit effort="30" lower="-1.57079632679" upper="1.57079632679" velocity="0.5"/>
  </joint>
  <transmission name="tran_head">
    <type>transmission_interface/SimpleTransmission</type>
    <joint name="joint_torso_to_head">
      <hardwareInterface>hardware_interface/EffortJointInterface</hardwareInterface>
    </joint>
    <actuator name="motor_head">
      <hardwareInterface>hardware_interface/EffortJointInterface</hardwareInterface>
      <mechanicalReduction>1</mechanicalReduction>
    </actuator>
  </transmission>
  <link name="base_scan_front" type="laser">
    <inertial>
      <mass value="0.01"/>
      <inertia ixx="9.75e-06" ixy="0.0" ixz="0.0" iyy="9.75e-06" iyz="0.0" izz="6e-06"/>
    </inertial>
    <collision name="collision">
      <origin rpy="0 0 0" xyz="0 0 0"/>
      <geometry>
        <box size="0.06 0.06 0.09"/>
      </geometry>
    </collision>
    <visual>
      <origin rpy="1.57079632679 0 0" xyz="0 0 0"/>
      <geometry>
        <mesh filename="package://hera_description/meshes/hokuyo_utm.stl"/>
      </geometry>
    </visual>
  </link>
  <joint name="base_scan_front_hokuyo_utm_joint" type="fixed">
    <origin rpy="0 0 0" xyz="0.3 0 0.01"/>
    <parent link="base"/>
    <child link="base_scan_front"/>
  </joint>
  <link name="base_scan_back" type="laser">
    <inertial>
      <mass value="0.01"/>
      <inertia ixx="6.16666666667e-06" ixy="0.0" ixz="0.0" iyy="6.16666666667e-06" iyz="0.0" izz="4.16666666667e-06"/>
    </inertial>
    <collision name="collision">
      <origin rpy="0 0 0" xyz="0 0 0"/>
      <geometry>
        <box size="0.05 0.05 0.07"/>
      </geometry>
    </collision>
    <visual>
      <origin rpy="0 0 0" xyz="0 0 0"/>
      <geometry>
        <mesh filename="package://hera_description/meshes/hokuyo_urg.dae"/>
      </geometry>
    </visual>
  </link>
  <joint name="joint_base_to_base_scan_back_hokuyo_urg" type="fixed">
    <origin rpy="0 0 3.14159265359" xyz="-0.3 0 0.01"/>
    <parent link="base"/>
    <child link="base_scan_back"/>
  </joint>
  <!-- xtion -->
  <link name="xtion">
    <inertial>
      <mass value="0.01"/>
      <inertia ixx="3.10833333333e-05" ixy="0.0" ixz="0.0" iyy="5.41666666667e-06" iyz="0.0" izz="2.83333333333e-05"/>
    </inertial>
    <collision name="collision">
      <origin rpy="0 0 0" xyz="0 0 0"/>
      <geometry>
        <box size="0.04 0.18 0.07"/>
      </geometry>
    </collision>
    <visual>
      <origin rpy="1.57079632679 0.0 1.57079632679" xyz="0.02 0.025 0"/>
      <geometry>
        <mesh filename="package://hera_description/meshes/asus_xtion.stl"/>
      </geometry>
    </visual>
  </link>
  <joint name="joint_torso_to_xtion" type="fixed">
    <origin rpy="0 0 0" xyz="0.1 0 -0.14"/>
    <parent link="torso"/>
    <child link="xtion"/>
  </joint>
  <link name="xtion_depth"/>
  <joint name="joint_xtion_to_xtion_depth" type="fixed">
    <origin rpy="0 0 0" xyz="0.0 0.049 0.016"/>
    <parent link="xtion"/>
    <child link="xtion_depth"/>
  </joint>
  <link name="xtion_optical"/>
  <joint name="joint_xtion_to_xtion_otptical" type="fixed">
    <origin rpy="-1.57079632679 0 -1.57079632679" xyz="0 0 0"/>
    <parent link="xtion"/>
    <child link="xtion_optical"/>
  </joint>
  <!-- kinect_one -->
  <link name="kinect_one">
    <inertial>
      <mass value="0.01"/>
      <inertia ixx="6.66666666667e-05" ixy="0.0" ixz="0.0" iyy="5.41666666667e-06" iyz="0.0" izz="6.94166666667e-05"/>
    </inertial>
    <collision name="collision">
      <origin rpy="0 0 0" xyz="-0.03 0 0"/>
      <geometry>
        <box size="0.07 0.28 0.04"/>
      </geometry>
    </collision>
    <visual>
      <origin rpy="0.0 0.0 0.0" xyz="0 -0.01 0"/>
      <geometry>
        <mesh filename="package://hera_description/meshes/kinect_one.stl"/>
      </geometry>
    </visual>
  </link>
  <joint name="joint_torso_sensor_plat_to_kinect_one" type="fixed">
    <origin rpy="0 0 0" xyz="0.05 0 0.1"/>
    <parent link="torso_sensor_plat"/>
    <child link="kinect_one"/>
  </joint>
  <link name="kinect_one_depth"/>
  <joint name="$joint_kinect_one_to_kinect_one_depth" type="fixed">
    <origin rpy="0 0 0" xyz="0.0 -0.049 0.0"/>
    <parent link="kinect_one"/>
    <child link="kinect_one_depth"/>
  </joint>
  <link name="kinect_one_optical"/>
  <joint name="joint_kinect_one_to_kinect_one_otptical" type="fixed">
    <origin rpy="-1.57079632679 0 -1.57079632679" xyz="0 0 0"/>
    <parent link="kinect_one"/>
    <child link="kinect_one_optical"/>
  </joint>
  <link name="suporte_link">
    <visual>
      <origin rpy="0 0 0" xyz="0 0 0"/>
      <geometry>
        <mesh filename="package://hera_description/meshes/manip_meshes/suporte_link.STL"/>
      </geometry>
      <material name="grey">
        <color rgba="0.792156862745098 0.819607843137255 0.933333333333333 1"/>
      </material>
    </visual>
    <collision>
      <origin rpy="0 0 0" xyz="0 0 0"/>
      <geometry>
        <mesh filename="package://hera_description/meshes/manip_meshes/suporte_link.STL"/>
      </geometry>
    </collision>
    <inertial>
      <origin rpy="0 0 0" xyz="0.099437810671345 2.00188811166901E-07 0.0198713294048926"/>
      <mass value="0.65921714068"/>
      <inertia ixx="0.000498685766551954" ixy="4.35797776215065E-09" ixz="-0.000221629766113691" iyy="0.00233391280566028" iyz="5.90356892037055E-09" izz="0.00260971250229957"/>
    </inertial>
  </link>
  <!--suporte_joint-->
  <joint name="suporte_joint" type="fixed">
    <origin rpy="0 0 0" xyz="0.04525 0 0.0285"/>
    <parent link="torso"/>
    <child link="suporte_link"/>
    <axis xyz="0 0 0"/>
    <limit effort="0" lower="0" upper="0" velocity="0"/>
  </joint>
  <link name="encosto_link">
    <visual>
      <origin rpy="0 0 0" xyz="0 0 0"/>
      <geometry>
        <mesh filename="package://hera_description/meshes/manip_meshes/encosto_link.STL"/>
      </geometry>
      <material name="grey">
        <color rgba="0.898039215686275 0.917647058823529 0.929411764705882 1"/>
      </material>
    </visual>
    <collision>
      <origin rpy="0 0 0" xyz="0 0 0"/>
      <geometry>
        <mesh filename="package://hera_description/meshes/manip_meshes/encosto_link.STL"/>
      </geometry>
    </collision>
    <inertial>
      <origin rpy="0 0 0" xyz="0.00030938336056912 -9.89895665437501E-13 0.0229511892881233"/>
      <mass value="0.0709912944889"/>
      <inertia ixx="5.65453718592828E-05" ixy="5.00162232371705E-16" ixz="-1.38639831470138E-06" iyy="0.000101241328443196" iyz="-3.18870100704921E-15" izz="8.47747908239031E-05"/>
    </inertial>
  </link>
  <!--encosto_joint-->
  <joint name="encosto_joint" type="fixed">
    <origin rpy="0 0 0" xyz="0.028 0.0066709 0.053"/>
    <parent link="torso"/>
    <child link="encosto_link"/>
    <axis xyz="0 0 0"/>
    <limit effort="0" velocity="0"/>
  </joint>
  <link name="base_link">
    <visual>
      <origin rpy="0 0 0" xyz="0 0 0"/>
      <geometry>
        <mesh filename="package://hera_description/meshes/manip_meshes/base_link.STL"/>
      </geometry>
      <material name="dark_grey">        
        </material>
    </visual>
    <collision>
      <origin rpy="0 0 0" xyz="0 0 0"/>
      <geometry>
        <mesh filename="package://hera_description/meshes/manip_meshes/base_link.STL"/>
      </geometry>
    </collision>
    <inertial>
      <origin rpy="0 0 0" xyz="0.00030938336056912 -9.89895665437501E-13 0.0229511892881233"/>
      <mass value="0.225814419605"/>
      <inertia ixx="5.65453718592828E-05" ixy="5.00162232371705E-16" ixz="-1.38639831470138E-06" iyy="0.000101241328443196" iyz="-3.18870100704921E-15" izz="8.47747908239031E-05"/>
    </inertial>
  </link>
  <!--base_joint-->
  <joint name="base_joint" type="fixed">
    <origin rpy="0 0 0" xyz="0.27075 0 0.0295"/>
    <parent link="suporte_link"/>
    <child link="base_link"/>
    <axis xyz="0 0 0"/>
    <limit effort="0" lower="0" upper="0" velocity="0"/>
  </joint>
  <link name="link_1">
    <visual>
      <origin rpy="0 0 0" xyz="0 0 0"/>
      <geometry>
        <mesh filename="package://hera_description/meshes/manip_meshes/link_1.STL"/>
      </geometry>
      <material name="dark_grey">
        <color rgba="0.996078431372549 0.996078431372549 1 1"/>
      </material>
    </visual>
    <collision>
      <origin rpy="0 0 0" xyz="0 0 0"/>
      <geometry>
        <mesh filename="package://hera_description/meshes/manip_meshes/link_1.STL"/>
      </geometry>
    </collision>
    <inertial>
      <origin rpy="0 0 0" xyz="0.010403379929175 1.63335446591584E-08 0.0169657675518438"/>
      <mass value="0.0289102664623"/>
      <inertia ixx="2.12284942933575E-05" ixy="2.48129475489142E-12" ixz="-1.76897405605609E-06" iyy="1.25993311294143E-05" iyz="3.2054762687646E-12" izz="2.59552674841784E-05"/>
    </inertial>
  </link>
  <!--joint_1-->
  <joint name="joint_1" type="revolute">
    <origin rpy="0 0 0" xyz="0.0155 0 0.04515"/>
    <parent link="base_link"/>
    <child link="link_1"/>
    <axis xyz="0 0 1"/>
    <limit effort="8" lower="-3.14" upper="3.14" velocity="5"/>
  </joint>
  <link name="link_2">
    <visual>
      <origin rpy="0 0 0" xyz="0 0 0"/>
      <geometry>
        <mesh filename="package://hera_description/meshes/manip_meshes/link_2.STL"/>
      </geometry>
      <material name="dark_grey">
        <color rgba="0.898039215686275 0.917647058823529 0.929411764705882 1"/>
      </material>
    </visual>
    <collision>
      <origin rpy="0 0 0" xyz="0 0 0"/>
      <geometry>
        <mesh filename="package://hera_description/meshes/manip_meshes/link_2_col.STL"/>
      </geometry>
    </collision>
    <inertial>
      <origin rpy="0 0 0" xyz="0.010403379929175 1.63335446591584E-08 0.0169657675518438"/>
      <mass value="0.611796741663"/>
      <inertia ixx="2.12284942933575E-05" ixy="2.48129475489142E-12" ixz="-1.76897405605609E-06" iyy="1.25993311294143E-05" iyz="3.2054762687646E-12" izz="2.59552674841784E-05"/>
    </inertial>
  </link>
  <!--joint_2-->
  <joint name="joint_2" type="revolute">
    <origin rpy="3.1416 -2 -3.1416" xyz="0.048 0 0.02285"/>
    <parent link="link_1"/>
    <child link="link_2"/>
    <axis xyz="0 1 0"/>
    <limit effort="8" lower="-2.355" upper="3.14" velocity="5"/>
  </joint>
  <link name="link_3">
    <visual>
      <origin rpy="0 0 0" xyz="0 0 0"/>
      <geometry>
        <mesh filename="package://hera_description/meshes/manip_meshes/link_3.STL"/>
      </geometry>
      <material name="dark_grey">
        <color rgba="0.996078431372549 0.996078431372549 1 1"/>
      </material>
    </visual>
    <collision>
      <origin rpy="0 0 0" xyz="0 0 0"/>
      <geometry>
        <mesh filename="package://hera_description/meshes/manip_meshes/link_3_col.STL"/>
      </geometry>
    </collision>
    <inertial>
      <origin rpy="0 0 0" xyz="0.010403379929175 1.63335446591584E-08 0.0169657675518438"/>
      <mass value="0.0289102660424"/>
      <inertia ixx="2.12284942933575E-05" ixy="2.48129475489142E-12" ixz="-1.76897405605609E-06" iyy="1.25993311294143E-05" iyz="3.2054762687646E-12" izz="2.59552674841784E-05"/>
    </inertial>
  </link>
  <!--joint_3-->
  <joint name="joint_3" type="revolute">
    <origin rpy="0 0 0" xyz="0.1439 0 0"/>
    <parent link="link_2"/>
    <child link="link_3"/>
    <axis xyz="1 0 0"/>
    <limit effort="8" lower="-3.14" upper="3.14" velocity="5"/>
  </joint>
  <link name="link_4">
    <visual>
      <origin rpy="0 0 0" xyz="0 0 0"/>
      <geometry>
        <mesh filename="package://hera_description/meshes/manip_meshes/link_4.STL"/>
      </geometry>
      <material name="dark_grey">
        <color rgba="0.898039215686275 0.917647058823529 0.929411764705882 1"/>
      </material>
    </visual>
    <collision>
      <origin rpy="0 0 0" xyz="0 0 0"/>
      <geometry>
        <mesh filename="package://hera_description/meshes/manip_meshes/link_4_col.STL"/>
      </geometry>
    </collision>
    <inertial>
      <origin rpy="0 0 0" xyz="0.010403379929175 1.63335446591584E-08 0.0169657675518438"/>
      <mass value="0.611796742119"/>
      <inertia ixx="2.12284942933575E-05" ixy="2.48129475489142E-12" ixz="-1.76897405605609E-06" iyy="1.25993311294143E-05" iyz="3.2054762687646E-12" izz="2.59552674841784E-05"/>
    </inertial>
  </link>
  <!--joint_4-->
  <joint name="joint_4" type="revolute">
    <origin rpy="0 -0.3927 0" xyz="0.02285 0 -0.048"/>
    <parent link="link_3"/>
    <child link="link_4"/>
    <axis xyz="0 -1 0"/>
    <limit effort="8" lower="-3.14" upper="1.0078" velocity="5"/>
  </joint>
  <link name="link_5">
    <visual>
      <origin rpy="0 0 0" xyz="0 0 0"/>
      <geometry>
        <mesh filename="package://hera_description/meshes/manip_meshes/link_5.STL"/>
      </geometry>
      <material name="dark_grey">
        <color rgba="0.898039215686275 0.917647058823529 0.929411764705882 1"/>
      </material>
    </visual>
    <collision>
      <origin rpy="0 0 0" xyz="0 0 0"/>
      <geometry>
        <mesh filename="package://hera_description/meshes/manip_meshes/link_5_col.STL"/>
      </geometry>
    </collision>
    <inertial>
      <origin rpy="0 0 0" xyz="0.0113429838803915 -3.46944695195361E-18 0"/>
      <mass value="0.0368976416562"/>
      <inertia ixx="1.95927087211338E-05" ixy="7.26329421268603E-21" ixz="-2.5410988417629E-21" iyy="7.36984687037621E-06" iyz="8.60646127431738E-21" izz="2.02402124370273E-05"/>
    </inertial>
  </link>
  <!--joint_5-->
  <joint name="joint_5" type="revolute">
    <origin rpy="0 0 0" xyz="0.1439 0 0"/>
    <parent link="link_4"/>
    <child link="link_5"/>
    <axis xyz="1 0 0"/>
    <limit effort="8" lower="-3.14" upper="3.14" velocity="5"/>
  </joint>
  <link name="link_6">
    <visual>
      <origin rpy="0 0 0" xyz="0 0 0"/>
      <geometry>
        <mesh filename="package://hera_description/meshes/manip_meshes/link_6.STL" scale="0.1 0.1 0.1"/>
      </geometry>
      <material name="dark_grey">
        <color rgba="0.898039215686275 0.917647058823529 0.929411764705882 1"/>
      </material>
    </visual>
    <collision>
      <origin rpy="0 0 0" xyz="0 0 0"/>
      <geometry>
        <mesh filename="package://hera_description/meshes/manip_meshes/link_6_col.STL" scale="0.1 0.1 0.1"/>
      </geometry>
    </collision>
    <inertial>
      <origin rpy="0 0 0" xyz="0.0386040770329412 -0.000322583154717528 0.000293719089379529"/>
      <mass value="0.482627734526"/>
      <inertia ixx="0.000146386226397184" ixy="-4.37085473836754E-07" ixz="-1.5900787088928E-13" iyy="0.000125206462596505" iyz="-1.1391259066856E-12" izz="0.000181710835049005"/>
    </inertial>
  </link>
  <!--joint_6-->
  <joint name="joint_6" type="revolute">
    <origin rpy="0 -0.3927 0" xyz="0.03885 0 0"/>
    <parent link="link_5"/>
    <child link="link_6"/>
    <axis xyz="0 -1 0"/>
    <limit effort="8" lower="-2.6232" upper="1.8262" velocity="5"/>
  </joint>
  <!-- link list -->
  <link name="finger_1_link_0">
    <visual>
      <origin rpy="0 0 0" xyz="0.020 0 0"/>
      <geometry>
        <mesh filename="package://hera_description/meshes/gripper_meshes/visual/link_0.dae" scale="0.7 0.7 0.7"/>
      </geometry>
      <material name="white">
        <color rgba="0 0 0 1"/>
      </material>
    </visual>
    <collision>
      <origin rpy="0 0 0" xyz="0.020 0 0"/>
      <geometry>
        <mesh filename="package://hera_description/meshes/gripper_meshes/collision/link_0.STL" scale="0.7 0.7 0.7"/>
      </geometry>
      <material name="yellow">
        <color rgba="0 1 1 1"/>
      </material>
    </collision>
    <inertial>
      <origin rpy="0 0 0" xyz="0 0 0"/>
      <mass value="0.05"/>
      <inertia ixx="0.01" ixy="-0.00002" ixz="0.00001" iyy="0.0008" iyz="0" izz="0.001"/>
    </inertial>
  </link>
  <link name="finger_1_link_1">
    <visual>
      <origin rpy="0 0 -0.52" xyz="0.050 -.028 0"/>
      <geometry>
        <mesh filename="package://hera_description/meshes/gripper_meshes/visual/link_1.dae" scale="0.7 0.7 0.7"/>
      </geometry>
      <material name="light grey"/>
    </visual>
    <collision>
      <origin rpy="0 0 -0.52" xyz="0.050 -.028 0"/>
      <geometry>
        <mesh filename="package://hera_description/meshes/gripper_meshes/collision/link_1.STL" scale="0.7 0.7 0.7"/>
      </geometry>
      <material name="yellow"/>
    </collision>
    <inertial>
      <origin rpy="0 0 0" xyz="0 0 0"/>
      <mass value="0.15"/>
      <inertia ixx="0.001859" ixy="-0.000376" ixz="0.000028" iyy="0.012756" iyz="0" izz="0.0024"/>
    </inertial>
  </link>
  <link name="finger_1_link_2">
    <!--
			NOTE: This link has an offset in the z-direction based on the models that were
			used to generate grap-it poses.  With the offset below the model appears visually
			correct, but it is suspect.
			-->
    <visual>
      <origin rpy="0 0 0" xyz="0.039 0 0.0075"/>
      <geometry>
        <mesh filename="package://hera_description/meshes/gripper_meshes/visual/link_2.dae" scale="0.7 0.7 0.7"/>
      </geometry>
      <material name="light grey"/>
    </visual>
    <collision>
      <origin rpy="0 0 0" xyz="0.039 0 0.0075"/>
      <geometry>
        <mesh filename="package://hera_description/meshes/gripper_meshes/collision/link_2.STL" scale="0.7 0.7 0.7"/>
      </geometry>
      <material name="yellow"/>
    </collision>
    <inertial>
      <origin rpy="0 0 0" xyz="0 0 0"/>
      <mass value="0.15"/>
      <inertia ixx="0.001859" ixy="-0.000376" ixz="0.000028" iyy="0.012756" iyz="0" izz="0.0024"/>
    </inertial>
  </link>
  <link name="finger_1_link_3">
    <visual>
      <origin rpy="0 0 0.52" xyz="0 0 0"/>
      <geometry>
        <mesh filename="package://hera_description/meshes/gripper_meshes/visual/link_3.dae" scale="0.7 0.7 0.7"/>
      </geometry>
      <material name="light grey"/>
    </visual>
    <collision>
      <origin rpy="0 0 0.52" xyz="0 0 0"/>
      <geometry>
        <mesh filename="package://hera_description/meshes/gripper_meshes/collision/link_3.STL" scale="0.7 0.7 0.7"/>
      </geometry>
      <material name="yellow"/>
    </collision>
    <inertial>
      <origin rpy="0 0 0" xyz="0 0 0"/>
      <mass value="0.05"/>
      <inertia ixx="0.001239" ixy="-0.000251" ixz="0.000019" iyy="0.00085" iyz="0" izz="0.001632"/>
    </inertial>
  </link>
  <!-- end of link list -->
  <!-- joint list -->
  <joint name="finger_1_joint_1" type="revolute">
    <parent link="finger_1_link_0"/>
    <child link="finger_1_link_1"/>
    <axis xyz="0 0 1"/>
    <origin rpy="0 0 0" xyz="0.01 0.0 0"/>
    <limit effort="100" lower="-0.6503" upper="1.0" velocity="100"/>
  </joint>
  <joint name="finger_1_joint_2" type="revolute">
    <parent link="finger_1_link_1"/>
    <child link="finger_1_link_2"/>
    <axis xyz="0 0 1"/>
    <origin rpy="0 0 -0.52" xyz="0.04 -0.025 0"/>
    <limit effort="100" lower="-0.2787" upper="1.0" velocity="100"/>
  </joint>
  <joint name="finger_1_joint_3" type="fixed">
    <parent link="finger_1_link_2"/>
    <child link="finger_1_link_3"/>
    <axis xyz="0 0 1"/>
    <origin rpy="0 0 0" xyz="0.039 0 0"/>
  </joint>
  <!-- end of joint list -->
  <!-- link list -->
  <link name="finger_2_link_0">
    <visual>
      <origin rpy="0 0 0" xyz="0.020 0 0"/>
      <geometry>
        <mesh filename="package://hera_description/meshes/gripper_meshes/visual/link_0.dae" scale="0.7 0.7 0.7"/>
      </geometry>
      <material name="white">
        <color rgba="0 0 0 1"/>
      </material>
    </visual>
    <collision>
      <origin rpy="0 0 0" xyz="0.020 0 0"/>
      <geometry>
        <mesh filename="package://hera_description/meshes/gripper_meshes/collision/link_0.STL" scale="0.7 0.7 0.7"/>
      </geometry>
      <material name="yellow">
        <color rgba="0 1 1 1"/>
      </material>
    </collision>
    <inertial>
      <origin rpy="0 0 0" xyz="0 0 0"/>
      <mass value="0.05"/>
      <inertia ixx="0.01" ixy="-0.00002" ixz="0.00001" iyy="0.0008" iyz="0" izz="0.001"/>
    </inertial>
  </link>
  <link name="finger_2_link_1">
    <visual>
      <origin rpy="0 0 -0.52" xyz="0.050 -.028 0"/>
      <geometry>
        <mesh filename="package://hera_description/meshes/gripper_meshes/visual/link_1.dae" scale="0.7 0.7 0.7"/>
      </geometry>
      <material name="light grey"/>
    </visual>
    <collision>
      <origin rpy="0 0 -0.52" xyz="0.050 -.028 0"/>
      <geometry>
        <mesh filename="package://hera_description/meshes/gripper_meshes/collision/link_1.STL" scale="0.7 0.7 0.7"/>
      </geometry>
      <material name="yellow"/>
    </collision>
    <inertial>
      <origin rpy="0 0 0" xyz="0 0 0"/>
      <mass value="0.15"/>
      <inertia ixx="0.001859" ixy="-0.000376" ixz="0.000028" iyy="0.012756" iyz="0" izz="0.0024"/>
    </inertial>
  </link>
  <link name="finger_2_link_2">
    <!--
			NOTE: This link has an offset in the z-direction based on the models that were
			used to generate grap-it poses.  With the offset below the model appears visually
			correct, but it is suspect.
			-->
    <visual>
      <origin rpy="0 0 0" xyz="0.039 0 0.0075"/>
      <geometry>
        <mesh filename="package://hera_description/meshes/gripper_meshes/visual/link_2.dae" scale="0.7 0.7 0.7"/>
      </geometry>
      <material name="light grey"/>
    </visual>
    <collision>
      <origin rpy="0 0 0" xyz="0.039 0 0.0075"/>
      <geometry>
        <mesh filename="package://hera_description/meshes/gripper_meshes/collision/link_2.STL" scale="0.7 0.7 0.7"/>
      </geometry>
      <material name="yellow"/>
    </collision>
    <inertial>
      <origin rpy="0 0 0" xyz="0 0 0"/>
      <mass value="0.15"/>
      <inertia ixx="0.001859" ixy="-0.000376" ixz="0.000028" iyy="0.012756" iyz="0" izz="0.0024"/>
    </inertial>
  </link>
  <link name="finger_2_link_3">
    <visual>
      <origin rpy="0 0 0.52" xyz="0 0 0"/>
      <geometry>
        <mesh filename="package://hera_description/meshes/gripper_meshes/visual/link_3.dae" scale="0.7 0.7 0.7"/>
      </geometry>
      <material name="light grey"/>
    </visual>
    <collision>
      <origin rpy="0 0 0.52" xyz="0 0 0"/>
      <geometry>
        <mesh filename="package://hera_description/meshes/gripper_meshes/collision/link_3.STL" scale="0.7 0.7 0.7"/>
      </geometry>
      <material name="yellow"/>
    </collision>
    <inertial>
      <origin rpy="0 0 0" xyz="0 0 0"/>
      <mass value="0.05"/>
      <inertia ixx="0.001239" ixy="-0.000251" ixz="0.000019" iyy="0.00085" iyz="0" izz="0.001632"/>
    </inertial>
  </link>
  <!-- end of link list -->
  <!-- joint list -->
  <joint name="finger_2_joint_1" type="revolute">
    <parent link="finger_2_link_0"/>
    <child link="finger_2_link_1"/>
    <axis xyz="0 0 1"/>
    <origin rpy="0 0 0" xyz="0.01 0.0 0"/>
    <limit effort="100" lower="-0.6503" upper="1.0" velocity="100"/>
  </joint>
  <joint name="finger_2_joint_2" type="revolute">
    <parent link="finger_2_link_1"/>
    <child link="finger_2_link_2"/>
    <axis xyz="0 0 1"/>
    <origin rpy="0 0 -0.52" xyz="0.04 -0.025 0"/>
    <limit effort="100" lower="-0.2787" upper="1.0" velocity="100"/>
  </joint>
  <joint name="finger_2_joint_3" type="fixed">
    <parent link="finger_2_link_2"/>
    <child link="finger_2_link_3"/>
    <axis xyz="0 0 1"/>
    <origin rpy="0 0 0" xyz="0.039 0 0"/>
  </joint>
  <!-- end of joint list -->
  <!-- link list -->
  <link name="finger_middle_link_0">
    <visual>
      <origin rpy="0 0 0" xyz="0.020 0 0"/>
      <geometry>
        <mesh filename="package://hera_description/meshes/gripper_meshes/visual/link_0.dae" scale="0.7 0.7 0.7"/>
      </geometry>
      <material name="white">
        <color rgba="0 0 0 1"/>
      </material>
    </visual>
    <collision>
      <origin rpy="0 0 0" xyz="0.020 0 0"/>
      <geometry>
        <mesh filename="package://hera_description/meshes/gripper_meshes/collision/link_0.STL" scale="0.7 0.7 0.7"/>
      </geometry>
      <material name="yellow">
        <color rgba="0 1 1 1"/>
      </material>
    </collision>
    <inertial>
      <origin rpy="0 0 0" xyz="0 0 0"/>
      <mass value="0.05"/>
      <inertia ixx="0.01" ixy="-0.00002" ixz="0.00001" iyy="0.0008" iyz="0" izz="0.001"/>
    </inertial>
  </link>
  <link name="finger_middle_link_1">
    <visual>
      <origin rpy="0 0 -0.52" xyz="0.050 -.028 0"/>
      <geometry>
        <mesh filename="package://hera_description/meshes/gripper_meshes/visual/link_1.dae" scale="0.7 0.7 0.7"/>
      </geometry>
      <material name="light grey"/>
    </visual>
    <collision>
      <origin rpy="0 0 -0.52" xyz="0.050 -.028 0"/>
      <geometry>
        <mesh filename="package://hera_description/meshes/gripper_meshes/collision/link_1.STL" scale="0.7 0.7 0.7"/>
      </geometry>
      <material name="yellow"/>
    </collision>
    <inertial>
      <origin rpy="0 0 0" xyz="0 0 0"/>
      <mass value="0.15"/>
      <inertia ixx="0.001859" ixy="-0.000376" ixz="0.000028" iyy="0.012756" iyz="0" izz="0.0024"/>
    </inertial>
  </link>
  <link name="finger_middle_link_2">
    <!--
			NOTE: This link has an offset in the z-direction based on the models that were
			used to generate grap-it poses.  With the offset below the model appears visually
			correct, but it is suspect.
			-->
    <visual>
      <origin rpy="0 0 0" xyz="0.039 0 0.0075"/>
      <geometry>
        <mesh filename="package://hera_description/meshes/gripper_meshes/visual/link_2.dae" scale="0.7 0.7 0.7"/>
      </geometry>
      <material name="light grey"/>
    </visual>
    <collision>
      <origin rpy="0 0 0" xyz="0.039 0 0.0075"/>
      <geometry>
        <mesh filename="package://hera_description/meshes/gripper_meshes/collision/link_2.STL" scale="0.7 0.7 0.7"/>
      </geometry>
      <material name="yellow"/>
    </collision>
    <inertial>
      <origin rpy="0 0 0" xyz="0 0 0"/>
      <mass value="0.15"/>
      <inertia ixx="0.001859" ixy="-0.000376" ixz="0.000028" iyy="0.012756" iyz="0" izz="0.0024"/>
    </inertial>
  </link>
  <link name="finger_middle_link_3">
    <visual>
      <origin rpy="0 0 0.52" xyz="0 0 0"/>
      <geometry>
        <mesh filename="package://hera_description/meshes/gripper_meshes/visual/link_3.dae" scale="0.7 0.7 0.7"/>
      </geometry>
      <material name="light grey"/>
    </visual>
    <collision>
      <origin rpy="0 0 0.52" xyz="0 0 0"/>
      <geometry>
        <mesh filename="package://hera_description/meshes/gripper_meshes/collision/link_3.STL" scale="0.7 0.7 0.7"/>
      </geometry>
      <material name="yellow"/>
    </collision>
    <inertial>
      <origin rpy="0 0 0" xyz="0 0 0"/>
      <mass value="0.05"/>
      <inertia ixx="0.001239" ixy="-0.000251" ixz="0.000019" iyy="0.00085" iyz="0" izz="0.001632"/>
    </inertial>
  </link>
  <!-- end of link list -->
  <!-- joint list -->
  <joint name="finger_middle_joint_1" type="revolute">
    <parent link="finger_middle_link_0"/>
    <child link="finger_middle_link_1"/>
    <axis xyz="0 0 1"/>
    <origin rpy="0 0 0" xyz="0.01 0.0 0"/>
    <limit effort="100" lower="-0.6503" upper="1.0" velocity="100"/>
  </joint>
  <joint name="finger_middle_joint_2" type="revolute">
    <parent link="finger_middle_link_1"/>
    <child link="finger_middle_link_2"/>
    <axis xyz="0 0 1"/>
    <origin rpy="0 0 -0.52" xyz="0.04 -0.025 0"/>
    <limit effort="100" lower="-0.2787" upper="1.0" velocity="100"/>
  </joint>
  <joint name="finger_middle_joint_3" type="fixed">
    <parent link="finger_middle_link_2"/>
    <child link="finger_middle_link_3"/>
    <axis xyz="0 0 1"/>
    <origin rpy="0 0 0" xyz="0.039 0 0"/>
  </joint>
  <!-- end of joint list -->
  <!-- link list -->
  <link name="palm">
    <visual>
      <geometry>
        <mesh filename="package://hera_description/meshes/gripper_meshes/visual/palm.dae" scale="0.7 0.7 0.7"/>
      </geometry>
      <material name="white">
        <color rgba="0 0 0 1"/>
      </material>
    </visual>
    <collision>
      <geometry>
        <mesh filename="package://hera_description/meshes/gripper_meshes/collision/palm.STL" scale="0.7 0.7 0.7"/>
      </geometry>
      <material name="yellow">
        <color rgba="0 1 1 1"/>
      </material>
    </collision>
  </link>
  <link name="tool0"/>
  <inertial>
    <origin rpy="0 0 0" xyz="0 0 0"/>
    <mass value="1.3"/>
    <inertia ixx="0.006012" ixy="0.000079" ixz="-0.00024" iyy="0.012892" iyz="0" izz="0.002435"/>
  </inertial>
  <!-- end of link list -->
  <!-- joint list -->
  <joint name="joint_palm" type="fixed">
    <origin rpy="0 0 -1.57" xyz="0.078 0 0"/>
    <parent link="link_6"/>
    <child link="palm"/>
  </joint>
  <joint name="palm_finger_1_joint" type="fixed">
    <parent link="palm"/>
    <child link="finger_1_link_0"/>
    <origin rpy="0 3.1416 -1.57" xyz="-0.0255 0.01 0.0225"/>
  </joint>
  <joint name="palm_finger_2_joint" type="fixed">
    <parent link="palm"/>
    <child link="finger_2_link_0"/>
    <origin rpy="0 3.1416 -1.57" xyz="-0.0255 0.01 -0.0225"/>
  </joint>
  <joint name="palm_finger_middle_joint" type="fixed">
    <parent link="palm"/>
    <child link="finger_middle_link_0"/>
    <origin rpy="0 0 1.57" xyz="0.0255 0.01 0"/>
  </joint>
  <joint name="palm_tool0" type="fixed">
    <parent link="palm"/>
    <child link="tool0"/>
    <origin rpy="0 0 1.5707" xyz="0.0 0.0875 0.0"/>
  </joint>
  <!-- end of joint list -->
  <transmission name="trans_1">
    <type>transmission_interface/SimpleTransmission</type>
    <joint name="joint_1">
      <hardwareInterface>hardware_interface/PositionJointInterface</hardwareInterface>
    </joint>
    <actuator name="joint_1_motor">
      <hardwareInterface>hardware_interface/PositionJointInterface</hardwareInterface>
      <mechanicalReduction>1</mechanicalReduction>
    </actuator>
  </transmission>
  <transmission name="trans_2">
    <type>transmission_interface/SimpleTransmission</type>
    <joint name="joint_2">
      <hardwareInterface>hardware_interface/PositionJointInterface</hardwareInterface>
    </joint>
    <actuator name="joint_2_motor">
      <hardwareInterface>hardware_interface/PositionJointInterface</hardwareInterface>
      <mechanicalReduction>1</mechanicalReduction>
    </actuator>
  </transmission>
  <transmission name="trans_3">
    <type>transmission_interface/SimpleTransmission</type>
    <joint name="joint_3">
      <hardwareInterface>hardware_interface/PositionJointInterface</hardwareInterface>
    </joint>
    <actuator name="joint_3_motor">
      <hardwareInterface>hardware_interface/PositionJointInterface</hardwareInterface>
      <mechanicalReduction>1</mechanicalReduction>
    </actuator>
  </transmission>
  <transmission name="trans_4">
    <type>transmission_interface/SimpleTransmission</type>
    <joint name="joint_4">
      <hardwareInterface>hardware_interface/PositionJointInterface</hardwareInterface>
    </joint>
    <actuator name="joint_4_motor">
      <hardwareInterface>hardware_interface/PositionJointInterface</hardwareInterface>
      <mechanicalReduction>1</mechanicalReduction>
    </actuator>
  </transmission>
  <transmission name="trans_5">
    <type>transmission_interface/SimpleTransmission</type>
    <joint name="joint_5">
      <hardwareInterface>hardware_interface/PositionJointInterface</hardwareInterface>
    </joint>
    <actuator name="joint_5_motor">
      <hardwareInterface>hardware_interface/PositionJointInterface</hardwareInterface>
      <mechanicalReduction>1</mechanicalReduction>
    </actuator>
  </transmission>
  <transmission name="trans_6">
    <type>transmission_interface/SimpleTransmission</type>
    <joint name="joint_6">
      <hardwareInterface>hardware_interface/PositionJointInterface</hardwareInterface>
    </joint>
    <actuator name="joint_6_motor">
      <hardwareInterface>hardware_interface/PositionJointInterface</hardwareInterface>
      <mechanicalReduction>1</mechanicalReduction>
    </actuator>
  </transmission>
  <!--##################### GRIPPER ########################-->
  <transmission name="trans_gripper_1">
    <type>transmission_interface/SimpleTransmission</type>
    <joint name="finger_1_joint_1">
      <hardwareInterface>hardware_interface/PositionJointInterface</hardwareInterface>
    </joint>
    <actuator name="finger_1_joint_1_motor">
      <hardwareInterface>hardware_interface/PositionJointInterface</hardwareInterface>
      <mechanicalReduction>1</mechanicalReduction>
    </actuator>
  </transmission>
  <transmission name="trans_gripper_2">
    <type>transmission_interface/SimpleTransmission</type>
    <joint name="finger_1_joint_2">
      <hardwareInterface>hardware_interface/PositionJointInterface</hardwareInterface>
    </joint>
    <actuator name="finger_1_joint_2_motor">
      <hardwareInterface>hardware_interface/PositionJointInterface</hardwareInterface>
      <mechanicalReduction>1</mechanicalReduction>
    </actuator>
  </transmission>
  <transmission name="trans_gripper_3">
    <type>transmission_interface/SimpleTransmission</type>
    <joint name="finger_2_joint_1">
      <hardwareInterface>hardware_interface/PositionJointInterface</hardwareInterface>
    </joint>
    <actuator name="finger_2_joint_1_motor">
      <hardwareInterface>hardware_interface/PositionJointInterface</hardwareInterface>
      <mechanicalReduction>1</mechanicalReduction>
    </actuator>
  </transmission>
  <transmission name="trans_gripper_4">
    <type>transmission_interface/SimpleTransmission</type>
    <joint name="finger_2_joint_2">
      <hardwareInterface>hardware_interface/PositionJointInterface</hardwareInterface>
    </joint>
    <actuator name="finger_2_joint_2_motor">
      <hardwareInterface>hardware_interface/PositionJointInterface</hardwareInterface>
      <mechanicalReduction>1</mechanicalReduction>
    </actuator>
  </transmission>
  <transmission name="trans_gripper_5">
    <type>transmission_interface/SimpleTransmission</type>
    <joint name="finger_middle_joint_1">
      <hardwareInterface>hardware_interface/PositionJointInterface</hardwareInterface>
    </joint>
    <actuator name="finger_middle_joint_1_motor">
      <hardwareInterface>hardware_interface/PositionJointInterface</hardwareInterface>
      <mechanicalReduction>1</mechanicalReduction>
    </actuator>
  </transmission>
  <transmission name="trans_gripper_5">
    <type>transmission_interface/SimpleTransmission</type>
    <joint name="finger_middle_joint_2">
      <hardwareInterface>hardware_interface/PositionJointInterface</hardwareInterface>
    </joint>
    <actuator name="finger_middle_joint_2_motor">
      <hardwareInterface>hardware_interface/PositionJointInterface</hardwareInterface>
      <mechanicalReduction>1</mechanicalReduction>
    </actuator>
  </transmission>
  <!-- ####################################################################### -->
  <!-- ####################### gazebo extensions ##############################-->
  <!-- ####################################################################### -->
  <gazebo>
    <plugin filename="libgazebo_ros_planar_move.so" name="base_controller">
      <commandTopic>cmd_vel</commandTopic>
      <odometryTopic>odom</odometryTopic>
      <odometryFrame>odom</odometryFrame>
      <odometryRate>100.0</odometryRate>
      <robotBaseFrame>base_footprint</robotBaseFrame>
    </plugin>
  </gazebo>
  <gazebo reference="base_scan_front">
    <sensor name="base_scan_front" type="ray">
      <always_on>true</always_on>
      <update_rate>30</update_rate>
      <visualize>true</visualize>
      <ray>
        <scan>
          <horizontal>
            <samples>150</samples>
            <resolution>1.0</resolution>
            <min_angle>-1.45</min_angle>
            <max_angle>1.45</max_angle>
          </horizontal>
        </scan>
        <range>
          <min>0.08</min>
          <max>30.0</max>
          <resolution>0.01</resolution>
        </range>
      </ray>
      <plugin filename="libgazebo_ros_laser.so" name="gazebo_ros_base_scan_front_controller">
        <gaussianNoise>0.005</gaussianNoise>
        <alwaysOn>true</alwaysOn>
        <updateRate>30</updateRate>
        <topicName>base_scan_front</topicName>
        <frameName>base_scan_front</frameName>
      </plugin>
    </sensor>
  </gazebo>
  <gazebo reference="base_scan_back">
    <sensor name="base_scan_back" type="ray">
      <always_on>true</always_on>
      <update_rate>30</update_rate>
      <visualize>true</visualize>
      <ray>
        <scan>
          <horizontal>
            <samples>150</samples>
            <resolution>1.0</resolution>
            <min_angle>-1.45</min_angle>
            <max_angle>1.45</max_angle>
          </horizontal>
        </scan>
        <range>
          <min>0.05</min>
          <max>5.6</max>
          <resolution>0.36</resolution>
        </range>
      </ray>
      <plugin filename="libgazebo_ros_laser.so" name="gazebo_ros_base_scan_back_controller">
        <gaussianNoise>0.005</gaussianNoise>
        <alwaysOn>true</alwaysOn>
        <updateRate>30</updateRate>
        <topicName>base_scan_back</topicName>
        <frameName>base_scan_back</frameName>
      </plugin>
    </sensor>
  </gazebo>
  <gazebo reference="xtion">
    <sensor name="xtion" type="depth">
      <always_on>true</always_on>
      <visualize>true</visualize>
      <update_rate>30</update_rate>
      <camera>
        <horizontal_fov>1.09606677025</horizontal_fov>
        <image>
          <format>R8G8B8</format>
          <width>32.0</width>
          <height>24.0</height>
        </image>
        <clip>
          <near>0.8</near>
          <far>3.5</far>
        </clip>
      </camera>
      <plugin filename="libgazebo_ros_openni_kinect.so" name="xtion_camera_controller">
        <alwaysOn>true</alwaysOn>
        <updateRate>30</updateRate>
        <cameraName>xtion</cameraName>
        <frameName>xtion_optical</frameName>
        <depthImageTopicName>depth/image_raw</depthImageTopicName>
        <depthImageCameraInfoTopicName>depth/camera_info</depthImageCameraInfoTopicName>
        <pointCloudTopicName>depth/points</pointCloudTopicName>
        <pointCloudCutoff>0.4</pointCloudCutoff>
        <hackBaseline>0.07</hackBaseline>
        <distortionK1>0.0</distortionK1>
        <distortionK2>0.0</distortionK2>
        <distortionK3>0.0</distortionK3>
        <distortionT1>0.0</distortionT1>
        <distortionT2>0.0</distortionT2>
        <CxPrime>0.0</CxPrime>
        <Cx>0.0</Cx>
        <Cy>0.0</Cy>
        <focalLength>0.0</focalLength>
      </plugin>
    </sensor>
  </gazebo>
  <gazebo reference="kinect_one">
    <sensor name="kinect_one" type="depth">
      <always_on>1</always_on>
      <visualize>true</visualize>
      <camera>
        <horizontal_fov>1.0471975512</horizontal_fov>
        <image>
          <format>R8G8B8</format>
          <width>1280</width>
          <height>720</height>
        </image>
        <clip>
          <near>0.4</near>
          <far>10</far>
        </clip>
      </camera>
      <plugin filename="libgazebo_ros_openni_kinect.so" name="{reference}_camera_controller">
        <alwaysOn>true</alwaysOn>
        <updateRate>30</updateRate>
        <cameraName>kinect_one</cameraName>
        <frameName>kinect_one_optical</frameName>
        <cameraInfoTopicName>rgb/camera_info</cameraInfoTopicName>
        <imageTopicName>rgb/image_raw</imageTopicName>
        <depthImageTopicName>depth/image_raw</depthImageTopicName>
        <depthImageCameraInfoTopicName>depth/camera_info</depthImageCameraInfoTopicName>
        <pointCloudTopicName>depth/points</pointCloudTopicName>
        <pointCloudCutoff>0.4</pointCloudCutoff>
        <hackBaseline>0.07</hackBaseline>
        <distortionK1>0.0</distortionK1>
        <distortionK2>0.0</distortionK2>
        <distortionK3>0.0</distortionK3>
        <distortionT1>0.0</distortionT1>
        <distortionT2>0.0</distortionT2>
        <CxPrime>0.0</CxPrime>
        <Cx>0.0</Cx>
        <Cy>0.0</Cy>
        <focalLength>0.0</focalLength>
      </plugin>
    </sensor>
  </gazebo>
  <gazebo>
    <plugin filename="libgazebo_ros_control.so" name="gazebo_ros_control">
      <robotNamespace>/kinect</robotNamespace>
      <robotSimType>gazebo_ros_control/DefaultRobotHWSim</robotSimType>
    </plugin>
  </gazebo>
  <gazebo>
    <plugin filename="libgazebo_ros_control.so" name="gazebo_ros_control">
      <robotNamespace>/manip</robotNamespace>
      <robotSimType>gazebo_ros_control/DefaultRobotHWSim</robotSimType>
    </plugin>
  </gazebo>
</robot>

