<?xml version="1.0"?>
<robot xmlns:xacro="http://www.ros.org/wiki/xacro" name="hera_description">

<xacro:include filename="$(find hera_description)/urdf/manip_prop.urdf.xacro"/>
<xacro:include filename="$(find hera_description)/urdf/simulation/manip_transmission.xacro"/>
<xacro:include filename="$(find hera_description)/urdf/actuators/gripper/robotiq-3f-gripper_articulated_macro.xacro"/>

<!--base_link-->
  <xacro:macro name="create_base_link">
    <link name="base_link">
      <visual>
        <origin xyz="0 0 0" rpy="0 0 0" />
        <geometry>
          <mesh filename="package://hera_description/meshes/manip_meshes/base_link.STL"/>
        </geometry>
        <material name="dark_grey">        
        </material>
      </visual>
      <collision>
        <origin xyz="0 0 0" rpy="0 0 0" />
        <geometry>
          <mesh filename="package://hera_description/meshes/manip_meshes/base_link.STL"/>
        </geometry>
      </collision>
      <xacro:inertial_base_link mass="0.225814419604843"/>
    </link>
  <!--base_joint-->
    <joint name="base_joint" type="fixed">
      <origin xyz="0.27075 0 0.0295" rpy="0 0 0" />
      <parent link="suporte_link" />
      <child link="base_link" />
      <axis xyz="0 0 0" />
      <limit lower="0" upper="0" effort="0" velocity="0" />
    </joint>
  </xacro:macro>

<!--link_1-->
  <xacro:macro name="create_link_1">
    <link name="link_1">
      <visual>
        <origin xyz="0 0 0" rpy="0 0 0" />
        <geometry>
          <mesh filename="package://hera_description/meshes/manip_meshes/link_1.STL"/>
        </geometry>
        <material name="dark_grey">
          <color rgba="0.996078431372549 0.996078431372549 1 1" />
        </material>
      </visual>
      <collision>
        <origin xyz="0 0 0" rpy="0 0 0" />
        <geometry>
          <mesh filename="package://hera_description/meshes/manip_meshes/link_1.STL"/>
        </geometry>
      </collision>
      <xacro:inertial_link_1 mass="0.0289102664622999"/>
    </link>

    <!--joint_1-->
    <joint name="joint_1" type="revolute">
      <origin xyz="0.0155 0 0.04515" rpy="0 0 0" />
      <parent link="base_link" />
      <child link="link_1" />
      <axis xyz="0 0 1" />
      <limit lower="-3.14" upper="3.14" effort="8" velocity="5" />
    </joint>
  </xacro:macro>

<!--link_2-->
  <xacro:macro name="create_link_2">
    <link name="link_2">
      <visual>
        <origin xyz="0 0 0" rpy="0 0 0" />
        <geometry>
          <mesh filename="package://hera_description/meshes/manip_meshes/link_2.STL"/>
        </geometry>
        <material name="dark_grey">
          <color rgba="0.898039215686275 0.917647058823529 0.929411764705882 1" />
        </material>
      </visual>
      <collision>
        <origin xyz="0 0 0" rpy="0 0 0" />
        <geometry>
          <mesh filename="package://hera_description/meshes/manip_meshes/link_2_col.STL"/>
        </geometry>
      </collision>
      <xacro:inertial_link_1 mass="0.611796741662792"/>
    </link>

    <!--joint_2--> 
    <joint name="joint_2" type="revolute">
      <origin xyz="0.048 0 0.02285" rpy="3.1416 -2 -3.1416" />
      <parent link="link_1" />
      <child link="link_2" />
      <axis xyz="0 1 0" />
      <limit lower="-2.355" upper="3.14" effort="8" velocity="5" />
    </joint>
  </xacro:macro>

<!--link_3-->
  <xacro:macro name="create_link_3">
    <link name="link_3">
      <visual>
        <origin xyz="0 0 0" rpy="0 0 0" />
        <geometry>
          <mesh filename="package://hera_description/meshes/manip_meshes/link_3.STL"/>
        </geometry>
        <material name="dark_grey">
          <color rgba="0.996078431372549 0.996078431372549 1 1" />
        </material>
      </visual>
      <collision>
        <origin xyz="0 0 0" rpy="0 0 0" />
        <geometry>
          <mesh filename="package://hera_description/meshes/manip_meshes/link_3_col.STL"/>
        </geometry>
      </collision>
      <xacro:inertial_link_1 mass="0.0289102660424069"/>
    </link>

    <!--joint_3-->  
    <joint name="joint_3" type="revolute">
      <origin xyz="0.1439 0 0" rpy="0 0 0" />
      <parent link="link_2" />
      <child link="link_3" />
      <axis xyz="1 0 0" />
      <limit lower="-3.14" upper="3.14" effort="8" velocity="5" />
    </joint>
  </xacro:macro>

<!--link_4-->
  <xacro:macro name="create_link_4">
    <link name="link_4">
      <visual>
        <origin xyz="0 0 0" rpy="0 0 0" />
        <geometry>
          <mesh filename="package://hera_description/meshes/manip_meshes/link_4.STL"/>
        </geometry>
        <material name="dark_grey">
          <color rgba="0.898039215686275 0.917647058823529 0.929411764705882 1" />
        </material>
      </visual>
      <collision>
        <origin xyz="0 0 0" rpy="0 0 0" />
        <geometry>
          <mesh filename="package://hera_description/meshes/manip_meshes/link_4_col.STL"/>
        </geometry>
      </collision>
      <xacro:inertial_link_1 mass="0.611796742118779"/>
    </link>

    <!--joint_4-->
    <joint name="joint_4" type="revolute">
      <origin xyz="0.02285 0 -0.048" rpy="0 -0.3927 0" />
      <parent link="link_3" />
      <child link="link_4" />
      <axis xyz="0 -1 0" />
      <limit lower="-3.14" upper="1.0078" effort="8" velocity="5" />
    </joint>
  </xacro:macro>

<!-- link 5 -->
  <xacro:macro name="create_link_5">
    <link name="link_5">
      <visual>
        <origin xyz="0 0 0" rpy="0 0 0"/>
        <geometry>
          <mesh  filename="package://hera_description/meshes/manip_meshes/link_5.STL" />
        </geometry>
        <material name="dark_grey">
          <color rgba="0.898039215686275 0.917647058823529 0.929411764705882 1"/>
        </material>
      </visual>
      <collision>
        <origin xyz="0 0 0" rpy="0 0 0"/>
        <geometry>
          <mesh filename="package://hera_description/meshes/manip_meshes/link_5_col.STL" />
        </geometry>
      </collision> 
      <xacro:inertial_link_5 mass="0.0368976416562371"/>
    </link>

    <!--joint_5--> 
    <joint name="joint_5" type="revolute">
      <origin xyz="0.1439 0 0" rpy="0 0 0" />
      <parent link="link_4" />
      <child link="link_5" />
      <axis xyz="1 0 0" />
      <limit lower="-3.14" upper="3.14" effort="8" velocity="5" />
    </joint>
  </xacro:macro>

<!-- link 6 -->
  <xacro:macro name="create_link_6">
    <link name="link_6">
      <visual>
        <origin xyz="0 0 0" rpy="0 0 0"/>
        <geometry>
          <mesh  filename="package://hera_description/meshes/manip_meshes/link_6.STL" scale="0.1 0.1 0.1" />
        </geometry>
        <material name="dark_grey">
          <color rgba="0.898039215686275 0.917647058823529 0.929411764705882 1"/>
        </material>
      </visual>
      <collision>
        <origin xyz="0 0 0" rpy="0 0 0"/>
        <geometry>
          <mesh filename="package://hera_description/meshes/manip_meshes/link_6_col.STL" scale="0.1 0.1 0.1" />
        </geometry>
        </collision>
        <xacro:inertial_link_6 mass="0.482627734525522"/> 
    </link>

    <!--joint_6-->
    <joint name="joint_6" type="revolute">
      <origin xyz="0.03885 0 0" rpy="0 -0.3927 0" />
      <parent link="link_5" />
      <child link="link_6" />
      <axis xyz="0 -1 0" />
      <limit lower="-2.6232" upper="1.8262" effort="8" velocity="5" />
    </joint>
  </xacro:macro>

  <xacro:macro name="manip">

    <!--base_link-->
    <xacro:create_base_link/>
    
    <!--link_1-->
    <xacro:create_link_1/>

    <!--link_2-->
    <xacro:create_link_2/>

    <!--link_3-->
    <xacro:create_link_3/>

    <!--link_4-->
    <xacro:create_link_4/>

    <!--link_5-->
    <xacro:create_link_5/>

    <!--link_6-->
    <xacro:create_link_6/>

    <!-- Gripper -->
    <xacro:robotiq-3f-gripper_articulated prefix=""/>

    <!--Transmission-->
    <xacro:manip_transmission/>

    
  </xacro:macro>

</robot>