<robot
  name="hera_description">
  <link
    name="base_link">
    <inertial>
      <origin
        xyz="-0.0378472205159159 -4.45763618397466E-08 0.342644249622605"
        rpy="0 0 0" />
      <mass
        value="20" />
      <inertia
        ixx="0.044064230209152"
        ixy="1.30625532944847E-06"
        ixz="0.00719294044752676"
        iyy="0.0704530976037132"
        iyz="-1.57888819011965E-06"
        izz="0.0263888679239557" />
    </inertial>
    <visual>
      <origin
        xyz="0 0 0"
        rpy="0 0 0" />
      <geometry>
        <mesh
          filename="package://hera_description/meshes/base_link.STL" />
      </geometry>
      <material
        name="">
        <color
          rgba="0.882352941176471 0.909803921568627 1 1" />
      </material>
    </visual>
    <collision>
      <origin
        xyz="0 0 0"
        rpy="0 0 0" />
      <geometry>
        <mesh
          filename="package://hera_description/meshes/base_link.STL" />
      </geometry>
    </collision>
  </link>
  <link
    name="wheelFL_link">
    <inertial>
      <origin
        xyz="-2.77555756156289E-17 -0.000127707075968042 0"
        rpy="0 0 0" />
      <mass
        value="24.2701476542873" />
      <inertia
        ixx="0"
        ixy="0"
        ixz="0"
        iyy="0"
        iyz="0"
        izz="0" />
    </inertial>
    <visual>
      <origin
        xyz="0 0 0"
        rpy="0 0 0" />
      <geometry>
        <mesh
          filename="package://hera_description/meshes/wheelFL_link.STL" />
      </geometry>
      <material
        name="">
        <color
          rgba="0.647058823529412 0.517647058823529 0 1" />
      </material>
    </visual>
    <collision>
      <origin
        xyz="0 0 0"
        rpy="0 0 0" />
      <geometry>
        <mesh
          filename="package://hera_description/meshes/wheelFL_link.STL" />
      </geometry>
    </collision>
  </link>
  <joint
    name="wheelFL_joint"
    type="continuous">
    <origin
      xyz="0.20648 0.21675 0"
      rpy="0 0 0" />
    <parent
      link="base_link" />
    <child
      link="wheelFL_link" />
    <axis
      xyz="0 1 0" />
    <limit
      effort="3.25"
      velocity="5" />
  </joint>
  <link
    name="wheelFR_link">
    <inertial>
      <origin
        xyz="0 0.000127707075968042 0"
        rpy="0 0 0" />
      <mass
        value="24.2701476542873" />
      <inertia
        ixx="0"
        ixy="0"
        ixz="0"
        iyy="0"
        iyz="0"
        izz="0" />
    </inertial>
    <visual>
      <origin
        xyz="0 0 0"
        rpy="0 0 0" />
      <geometry>
        <mesh
          filename="package://hera_description/meshes/wheelFR_link.STL" />
      </geometry>
      <material
        name="">
        <color
          rgba="0.647058823529412 0.517647058823529 0 1" />
      </material>
    </visual>
    <collision>
      <origin
        xyz="0 0 0"
        rpy="0 0 0" />
      <geometry>
        <mesh
          filename="package://hera_description/meshes/wheelFR_link.STL" />
      </geometry>
    </collision>
  </link>
  <joint
    name="wheelFR_joint"
    type="continuous">
    <origin
      xyz="0.20648 -0.21675 0"
      rpy="0 0 0" />
    <parent
      link="base_link" />
    <child
      link="wheelFR_link" />
    <axis
      xyz="0 1 0" />
    <limit
      effort="3.25"
      velocity="5" />
  </joint>
  <link
    name="wheelBL_link">
    <inertial>
      <origin
        xyz="0 -0.000127707075968042 0"
        rpy="0 0 0" />
      <mass
        value="24.2701476542873" />
      <inertia
        ixx="0"
        ixy="0"
        ixz="0"
        iyy="0"
        iyz="0"
        izz="0" />
    </inertial>
    <visual>
      <origin
        xyz="0 0 0"
        rpy="0 0 0" />
      <geometry>
        <mesh
          filename="package://hera_description/meshes/wheelBL_link.STL" />
      </geometry>
      <material
        name="">
        <color
          rgba="0.647058823529412 0.517647058823529 0 1" />
      </material>
    </visual>
    <collision>
      <origin
        xyz="0 0 0"
        rpy="0 0 0" />
      <geometry>
        <mesh
          filename="package://hera_description/meshes/wheelBL_link.STL" />
      </geometry>
    </collision>
  </link>
  <joint
    name="wheelBL_joint"
    type="continuous">
    <origin
      xyz="-0.20623 0.21675 0"
      rpy="0 0 0" />
    <parent
      link="base_link" />
    <child
      link="wheelBL_link" />
    <axis
      xyz="0 1 0" />
    <limit
      effort="3.25"
      velocity="5" />
  </joint>
  <link
    name="wheelBR_link">
    <inertial>
      <origin
        xyz="0 0.000127707075968042 6.93889390390723E-18"
        rpy="0 0 0" />
      <mass
        value="24.2701476542873" />
      <inertia
        ixx="0"
        ixy="0"
        ixz="0"
        iyy="0"
        iyz="0"
        izz="0" />
    </inertial>
    <visual>
      <origin
        xyz="0 0 0"
        rpy="0 0 0" />
      <geometry>
        <mesh
          filename="package://hera_description/meshes/wheelBR_link.STL" />
      </geometry>
      <material
        name="">
        <color
          rgba="0.647058823529412 0.517647058823529 0 1" />
      </material>
    </visual>
    <collision>
      <origin
        xyz="0 0 0"
        rpy="0 0 0" />
      <geometry>
        <mesh
          filename="package://hera_description/meshes/wheelBR_link.STL" />
      </geometry>
    </collision>
  </link>
  <joint
    name="wheelBR_joint"
    type="continuous">
    <origin
      xyz="-0.20623 -0.21675 0"
      rpy="0 0 0" />
    <parent
      link="base_link" />
    <child
      link="wheelBR_link" />
    <axis
      xyz="0 1 0" />
    <limit
      effort="3.25"
      velocity="5" />
  </joint>
  <link
    name="base_scan_link">
    <inertial>
      <origin
        xyz="-0.00172501697333638 -4.93002948039427E-13 -0.0147337457873118"
        rpy="0 0 0" />
      <mass
        value="0.669181583389372" />
      <inertia
        ixx="0.000378278931511382"
        ixy="-2.04265599379836E-17"
        ixz="1.4632315095333E-06"
        iyy="0.000378287917620533"
        iyz="9.23792313122111E-15"
        izz="8.98610915070338E-09" />
    </inertial>
    <visual>
      <origin
        xyz="0 0 0"
        rpy="0 0 0" />
      <geometry>
        <mesh
          filename="package://hera_description/meshes/base_scan_link.STL" />
      </geometry>
      <material
        name="">
        <color
          rgba="0.898039215686275 0.917647058823529 0.929411764705882 1" />
      </material>
    </visual>
    <collision>
      <origin
        xyz="0 0 0"
        rpy="0 0 0" />
      <geometry>
        <mesh
          filename="package://hera_description/meshes/base_scan_link.STL" />
      </geometry>
    </collision>
  </link>
  <joint
    name="base_scan_joint"
    type="fixed">
    <origin
      xyz="0.29379 0 0.013419"
      rpy="0 0 0" />
    <parent
      link="base_link" />
    <child
      link="base_scan_link" />
    <axis
      xyz="0 0 0" />
  </joint>
  <link
    name="xtion_link">
    <inertial>
      <origin
        xyz="-0.0214204948659581 -4.24610953899513E-10 -0.000813578798952275"
        rpy="0 0 0" />
      <mass
        value="0.012280323128001" />
      <inertia
        ixx="0"
        ixy="0"
        ixz="0"
        iyy="0"
        iyz="0"
        izz="0" />
    </inertial>
    <visual>
      <origin
        xyz="0 0 0"
        rpy="0 0 0" />
      <geometry>
        <mesh
          filename="package://hera_description/meshes/xtion_link.STL" />
      </geometry>
      <material
        name="">
        <color
          rgba="1 1 1 0.32" />
      </material>
    </visual>
    <collision>
      <origin
        xyz="0 0 0"
        rpy="0 0 0" />
      <geometry>
        <mesh
          filename="package://hera_description/meshes/xtion_link.STL" />
      </geometry>
    </collision>
  </link>
  <joint
    name="xtion_joint"
    type="fixed">
    <origin
      xyz="0.0775 0 0.3873"
      rpy="0 0 0" />
    <parent
      link="base_link" />
    <child
      link="xtion_link" />
    <axis
      xyz="0 1 0" />
    <limit
      effort="0"
      velocity="0" />
  </joint>
  <link
    name="xtion_depth_optical">
    <inertial>
      <origin
        xyz="-0.0167798361475048 -0.0447871333667723 -0.000201032384153421"
        rpy="0 0 0" />
      <mass
        value="0.160828442414892" />
      <inertia
        ixx="0"
        ixy="0"
        ixz="0"
        iyy="0"
        iyz="0"
        izz="0" />
    </inertial>
    <visual>
      <origin
        xyz="0 0 0"
        rpy="0 0 0" />
      <geometry>
        <mesh
          filename="package://hera_description/meshes/xtion_depth_optical.STL" />
      </geometry>
      <material
        name="">
        <color
          rgba="1 1 1 0.32" />
      </material>
    </visual>
    <collision>
      <origin
        xyz="0 0 0"
        rpy="0 0 0" />
      <geometry>
        <mesh
          filename="package://hera_description/meshes/xtion_depth_optical.STL" />
      </geometry>
    </collision>
  </link>
  <joint
    name="xtion_depth_optical_joint"
    type="fixed">
    <origin
      xyz="0.016 0.0445000000000008 0.0214843769443395"
      rpy="0 0 0" />
    <parent
      link="xtion_link" />
    <child
      link="xtion_depth_optical" />
    <axis
      xyz="0 0 0" />
  </joint>
  <link
    name="manip_link">
    <inertial>
      <origin
        xyz="0.00670680348818703 3.974947148317E-09 0.0318456490768535"
        rpy="0 0 0" />
      <mass
        value="0.117793912097688" />
      <inertia
        ixx="3.51059975475259E-05"
        ixy="-8.98830903989E-12"
        ixz="-2.22633738741355E-05"
        iyy="4.92248903546142E-05"
        iyz="-1.41732136779733E-11"
        izz="1.41188928070997E-05" />
    </inertial>
    <visual>
      <origin
        xyz="0 0 0"
        rpy="0 0 0" />
      <geometry>
        <mesh
          filename="package://hera_description/meshes/manip_link.STL" />
      </geometry>
      <material
        name="">
        <color
          rgba="0.792156862745098 0.819607843137255 0.933333333333333 1" />
      </material>
    </visual>
    <collision>
      <origin
        xyz="0 0 0"
        rpy="0 0 0" />
      <geometry>
        <mesh
          filename="package://hera_description/meshes/manip_link.STL" />
      </geometry>
    </collision>
  </link>
  <joint
    name="manip_joint"
    type="fixed">
    <origin
      xyz="0.316 0 0.5923"
      rpy="0 0 0" />
    <parent
      link="base_link" />
    <child
      link="manip_link" />
    <axis
      xyz="0 0 0" />
  </joint>
  <link
    name="link_1">
    <inertial>
      <origin
        xyz="0.0104033798877035 1.61957894568264E-08 0.0156157675149726"
        rpy="0 0 0" />
      <mass
        value="0.0289102663054045" />
      <inertia
        ixx="0"
        ixy="0"
        ixz="0"
        iyy="0"
        iyz="0"
        izz="0" />
    </inertial>
    <visual>
      <origin
        xyz="0 0 0"
        rpy="0 0 0" />
      <geometry>
        <mesh
          filename="package://hera_description/meshes/link_1.STL" />
      </geometry>
      <material
        name="">
        <color
          rgba="0.996078431372549 0.996078431372549 1 1" />
      </material>
    </visual>
    <collision>
      <origin
        xyz="0 0 0"
        rpy="0 0 0" />
      <geometry>
        <mesh
          filename="package://hera_description/meshes/link_1.STL" />
      </geometry>
    </collision>
  </link>
  <joint
    name="joint_1"
    type="fixed">
    <origin
      xyz="0.0155 0 0.0465"
      rpy="0 0 0" />
    <parent
      link="manip_link" />
    <child
      link="link_1" />
    <axis
      xyz="0 0 1" />
    <limit
      effort="10.6"
      velocity="5" />
  </joint>
  <link
    name="link_2">
    <inertial>
      <origin
        xyz="0.0741364452821117 1.30229255655455E-17 0.00628031610796598"
        rpy="0 0 0" />
      <mass
        value="0.375828736783438" />
      <inertia
        ixx="0"
        ixy="0"
        ixz="0"
        iyy="0"
        iyz="0"
        izz="0" />
    </inertial>
    <visual>
      <origin
        xyz="0 0 0"
        rpy="0 0 0" />
      <geometry>
        <mesh
          filename="package://hera_description/meshes/link_2.STL" />
      </geometry>
      <material
        name="">
        <color
          rgba="0.792156862745098 0.819607843137255 0.933333333333333 1" />
      </material>
    </visual>
    <collision>
      <origin
        xyz="0 0 0"
        rpy="0 0 0" />
      <geometry>
        <mesh
          filename="package://hera_description/meshes/link_2.STL" />
      </geometry>
    </collision>
  </link>
  <joint
    name="joint_2"
    type="fixed">
    <origin
      xyz="0.048 0 0.0215"
      rpy="3.1416 -0.8154 -3.1416" />
    <parent
      link="link_1" />
    <child
      link="link_2" />
    <axis
      xyz="0 -1 0" />
    <limit
      effort="10.6"
      velocity="5" />
  </joint>
  <link
    name="link_3">
    <inertial>
      <origin
        xyz="0.0156157675773119 1.6417634019545E-08 -0.0104033799815866"
        rpy="0 0 0" />
      <mass
        value="0.0289102659811359" />
      <inertia
        ixx="0"
        ixy="0"
        ixz="0"
        iyy="0"
        iyz="0"
        izz="0" />
    </inertial>
    <visual>
      <origin
        xyz="0 0 0"
        rpy="0 0 0" />
      <geometry>
        <mesh
          filename="package://hera_description/meshes/link_3.STL" />
      </geometry>
      <material
        name="">
        <color
          rgba="0.996078431372549 0.996078431372549 1 1" />
      </material>
    </visual>
    <collision>
      <origin
        xyz="0 0 0"
        rpy="0 0 0" />
      <geometry>
        <mesh
          filename="package://hera_description/meshes/link_3.STL" />
      </geometry>
    </collision>
  </link>
  <joint
    name="joint_3"
    type="fixed">
    <origin
      xyz="0.14525 0 0"
      rpy="0 -5.5511E-17 -4.9304E-32" />
    <parent
      link="link_2" />
    <child
      link="link_3" />
    <axis
      xyz="1 0 0" />
    <limit
      effort="10.6"
      velocity="5" />
  </joint>
  <link
    name="link_4">
    <inertial>
      <origin
        xyz="0.0741364452820953 1.48160807624323E-13 0.00628031610795943"
        rpy="0 0 0" />
      <mass
        value="0.375828736783437" />
      <inertia
        ixx="0"
        ixy="0"
        ixz="0"
        iyy="0"
        iyz="0"
        izz="0" />
    </inertial>
    <visual>
      <origin
        xyz="0 0 0"
        rpy="0 0 0" />
      <geometry>
        <mesh
          filename="package://hera_description/meshes/link_4.STL" />
      </geometry>
      <material
        name="">
        <color
          rgba="0.792156862745098 0.819607843137255 0.933333333333333 1" />
      </material>
    </visual>
    <collision>
      <origin
        xyz="0 0 0"
        rpy="0 0 0" />
      <geometry>
        <mesh
          filename="package://hera_description/meshes/link_4.STL" />
      </geometry>
    </collision>
  </link>
  <joint
    name="joint_4"
    type="fixed">
    <origin
      xyz="0.0215 0.0001535 -0.048"
      rpy="8.3578E-18 -0.4681 -2.9674E-16" />
    <parent
      link="link_3" />
    <child
      link="link_4" />
    <axis
      xyz="0 -1 0" />
    <limit
      effort="10.6"
      velocity="5" />
  </joint>
  <link
    name="link_5">
    <inertial>
      <origin
        xyz="0.010087101628525 1.48136575705768E-13 -6.77236045021345E-15"
        rpy="0 0 0" />
      <mass
        value="0.0141181825481306" />
      <inertia
        ixx="0"
        ixy="0"
        ixz="0"
        iyy="0"
        iyz="0"
        izz="0" />
    </inertial>
    <visual>
      <origin
        xyz="0 0 0"
        rpy="0 0 0" />
      <geometry>
        <mesh
          filename="package://hera_description/meshes/link_5.STL" />
      </geometry>
      <material
        name="">
        <color
          rgba="0.792156862745098 0.819607843137255 0.933333333333333 1" />
      </material>
    </visual>
    <collision>
      <origin
        xyz="0 0 0"
        rpy="0 0 0" />
      <geometry>
        <mesh
          filename="package://hera_description/meshes/link_5.STL" />
      </geometry>
    </collision>
  </link>
  <joint
    name="joint_5"
    type="fixed">
    <origin
      xyz="0.14525 0 0"
      rpy="-0.0090 1.4438E-31 -8.5251E-17" />
    <parent
      link="link_4" />
    <child
      link="link_5" />
    <axis
      xyz="1 0 0" />
    <limit
      effort="10.6"
      velocity="5" />
  </joint>
  <link
    name="link_6">
    <inertial>
      <origin
        xyz="0.0426969278796748 1.47804755630879E-13 0.0176856465994266"
        rpy="0 0 0" />
      <mass
        value="0.23859359410415" />
      <inertia
        ixx="8.93099227661008E-05"
        ixy="-2.04409858272724E-17"
        ixz="-5.33316339200297E-05"
        iyy="0.000150844639986451"
        iyz="-8.64121315512775E-18"
        izz="0.000195973190606168" />
    </inertial>
    <visual>
      <origin
        xyz="0 0 0"
        rpy="0 0 0" />
      <geometry>
        <mesh
          filename="package://hera_description/meshes/link_6.STL" />
      </geometry>
      <material
        name="">
        <color
          rgba="0.792156862745098 0.819607843137255 0.933333333333333 1" />
      </material>
    </visual>
    <collision>
      <origin
        xyz="0 0 0"
        rpy="0 0 0" />
      <geometry>
        <mesh
          filename="package://hera_description/meshes/link_6.STL" />
      </geometry>
    </collision>
  </link>
  <joint
    name="joint_6"
    type="fixed">
    <origin
      xyz="0.0375 0 0"
      rpy="0 2.6196 0" />
    <parent
      link="link_5" />
    <child
      link="link_6" />
    <axis
      xyz="0 -1 0" />
    <limit
      effort="10.6"
      velocity="5" />
  </joint>
  <link
    name="link_7">
    <inertial>
      <origin
        xyz="0.000799658923762936 -5.81362093582914E-08 -2.0959335822468E-08"
        rpy="0 0 0" />
      <mass
        value="0.107040413919575" />
      <inertia
        ixx="0.000469215991711516"
        ixy="4.61057822637853E-11"
        ixz="5.0144351564635E-19"
        iyy="4.58551606653143E-18"
        iyz="-5.08471341484018E-12"
        izz="0.000469215991711521" />
    </inertial>
    <visual>
      <origin
        xyz="0 0 0"
        rpy="0 0 0" />
      <geometry>
        <mesh
          filename="package://hera_description/meshes/link_7.STL" />
      </geometry>
      <material
        name="">
        <color
          rgba="0.898039215686275 0.917647058823529 0.929411764705882 1" />
      </material>
    </visual>
    <collision>
      <origin
        xyz="0 0 0"
        rpy="0 0 0" />
      <geometry>
        <mesh
          filename="package://hera_description/meshes/link_7.STL" />
      </geometry>
    </collision>
  </link>
  <joint
    name="joint_7"
    type="fixed">
    <origin
      xyz="0.11762 0 0.04872"
      rpy="2.9899E-16 -0.3927 -1.9936E-16" />
    <parent
      link="link_6" />
    <child
      link="link_7" />
    <axis
      xyz="0 0 0" />
    <limit
      effort="10.6"
      velocity="0" />
  </joint>
  <link
    name="link_8" />
  <joint
    name="joint_8"
    type="fixed">
    <origin
      xyz="0.062599 0 0"
      rpy="0 3.0458E-31 0" />
    <parent
      link="link_7" />
    <child
      link="link_8" />
    <axis
      xyz="0 0 0" />
    <limit
      effort="10.6"
      velocity="0" />
  </joint>
  <link
    name="kinect_link">
    <inertial>
      <origin
        xyz="0.0174731660530447 0.000165436078301785 0.0325759125542562"
        rpy="0 0 0" />
      <mass
        value="0.0956443898933828" />
      <inertia
        ixx="0"
        ixy="0"
        ixz="0"
        iyy="0"
        iyz="0"
        izz="0" />
    </inertial>
    <visual>
      <origin
        xyz="0 0 0"
        rpy="0 0 0" />
      <geometry>
        <mesh
          filename="package://hera_description/meshes/kinect_link.STL" />
      </geometry>
      <material
        name="">
        <color
          rgba="1 1 1 1" />
      </material>
    </visual>
    <collision>
      <origin
        xyz="0 0 0"
        rpy="0 0 0" />
      <geometry>
        <mesh
          filename="package://hera_description/meshes/kinect_link.STL" />
      </geometry>
    </collision>
  </link>
  <joint
    name="kinect_joint"
    type="fixed">
    <origin
      xyz="0.077635 0 0.99883"
      rpy="6.0338E-16 0 0" />
    <parent
      link="base_link" />
    <child
      link="kinect_link" />
    <axis
      xyz="0 1 0" />
    <!-- <limit
      lower="0"
      upper="1.57"
      effort="3"
      velocity="3" /> -->
  </joint>
  <link
    name="camera_link">
    <inertial>
      <origin
        xyz="-0.0249439013422586 0.0101695683720893 -0.00338860098947635"
        rpy="0 0 0" />
      <mass
        value="0.601627894799159" />
      <inertia
        ixx="5.990327152102E-05"
        ixy="1.49751784865378E-07"
        ixz="1.87108228809937E-05"
        iyy="6.57441457584246E-05"
        iyz="-4.79404209175574E-07"
        izz="5.84854804592201E-06" />
    </inertial>
    <visual>
      <origin
        xyz="0 0 0"
        rpy="0 0 0" />
      <geometry>
        <mesh
          filename="package://hera_description/meshes/camera_link.STL" />
      </geometry>
      <material
        name="">
        <color
          rgba="0.298039215686275 0.298039215686275 0.298039215686275 1" />
      </material>
    </visual>
    <collision>
      <origin
        xyz="0 0 0"
        rpy="0 0 0" />
      <geometry>
        <mesh
          filename="package://hera_description/meshes/camera_link.STL" />
      </geometry>
    </collision>
  </link>
  <joint
    name="camera_joint"
    type="fixed">
    <origin
      xyz="0.0489731680776693 -0.00991907062292097 0.0979999999999999"
      rpy="-6.03382078600628E-16 1.07182188209377E-30 1.77635683940025E-15" />
    <parent
      link="kinect_link" />
    <child
      link="camera_link" />
    <axis
      xyz="0 0 0" />
  </joint>
  <link
    name="head_link">
    <inertial>
      <origin
        xyz="-0.013849039370921 -6.03535467358075E-09 0.189580167582216"
        rpy="0 0 0" />
      <mass
        value="8.0744855416889" />
      <inertia
        ixx="0"
        ixy="0"
        ixz="0"
        iyy="0"
        iyz="0"
        izz="0" />
    </inertial>
    <visual>
      <origin
        xyz="0 0 0"
        rpy="0 0 0" />
      <geometry>
        <mesh
          filename="package://hera_description/meshes/head_link.STL" />
      </geometry>
      <material
        name="">
        <color
          rgba="0.792156862745098 0.819607843137255 0.933333333333333 1" />
      </material>
    </visual>
    <collision>
      <origin
        xyz="0 0 0"
        rpy="0 0 0" />
      <geometry>
        <mesh
          filename="package://hera_description/meshes/head_link.STL" />
      </geometry>
    </collision>
  </link>
  <joint
    name="head_joint"
    type="fixed">
    <origin
      xyz="-0.0575 0 1.0193"
      rpy="0 0 1.2616E-16" />
    <parent
      link="base_link" />
    <child
      link="head_link" />
    <axis
      xyz="0 0 0" />
  </joint>
  <gazebo>
    <plugin name="base_controller" filename="libgazebo_ros_planar_move.so">
      <commandTopic>cmd_vel</commandTopic>
      <odometryTopic>odom</odometryTopic>
      <odometryFrame>odom</odometryFrame>
      <odometryRate>100.0</odometryRate>
      <robotBaseFrame>base_footprint</robotBaseFrame>
    </plugin>
  </gazebo>
  <gazebo reference="base_scan_link">
    <sensor name="base_scan" type="ray">
      <always_on>true</always_on>
      <update_rate>10</update_rate>
    	<visualize>true</visualize>
  	  <ray>
        <scan>
          <horizontal>
            <samples>150</samples>
            <resolution>1.0</resolution>
            <min_angle>-1.45</min_angle>
            <max_angle>1.45</max_angle>
          </horizontal>
        </scan>
        <range>
          <min>0.08</min>
          <max>30.0</max>
          <resolution>0.01</resolution>
        </range>
      </ray>
      <plugin name="gazebo_ros_base_scan_controller" filename="libgazebo_ros_laser.so">
        <gaussianNoise>0.005</gaussianNoise>
        <alwaysOn>true</alwaysOn>
        <updateRate>10</updateRate>
        <topicName>base_scan</topicName>
        <frameName>base_scan_link</frameName>
      </plugin>
    </sensor>
  </gazebo>
</robot>
